Workbook

Sheet Guide
B1: Project Management KPI Tracker – User Guide
B2: Covers all 16 KPIs: target setting → data capture → automatic calculation → RAG monitoring → corrective actions → verified improvement.
B4: HOW IT WORKS – MONTHLY CYCLE
B5: 1. Set targets | C5: KPI_Targets: set Target, Amber limit, Direction and Owner for each KPI. Any later change → one row in Target_Revisions (date, old/new, reason, approver).
B6: 2. Capture data | C6: Fill the green-tab logs during the month (Projects, Cost_Schedule, Change_Log, Risk_Log, Issue_Log, Stakeholder_Survey, Resources, Milestones, Quality_Log, Benefits_Log, CI_Log). Only type in YELLOW cells; grey cells calculate.
B7: 3. Review | C7: KPI_Tracking calculates every KPI per month and colours it GREEN / AMBER / RED. Dashboard shows the selected month, trend vs previous month and the portfolio snapshot. Trends shows all 16 charts.
B8: 4. Act | C8: For every AMBER/RED KPI open a row in Action_Log: value before, root cause, action, owner, due date. Due status flags OVERDUE automatically.
B9: 5. Verify the change | C9: When implemented, enter the date and the KPI value after. 'Result' shows Improved / No change / Worse (direction-aware). Process improvements go to CI_Log with 'Benefit verified'.
B10: 6. Close the month | C10: Settings › Current reporting month defaults to today's month. Overwrite it with a fixed date to freeze a reported period.
B12: SHEET MAP
B13: Dashboard | C13: One-page view: RAG tiles, 16 KPI table (target, actual, previous, trend, status, actions), portfolio snapshot, 7 charts.
B14: KPI_Tracking | C14: Engine: monthly actuals (12 months) for all 16 KPIs, latest value, RAG grid, count of GREEN/AMBER/RED per month.
B15: Trends | C15: 16 charts – bars = actual, dashed red line = target.
B16: KPI_Targets | C16: Definitions, calculation method, unit, direction, target, amber limit, owner, watch-outs.
B17: Target_Revisions | C17: Audit trail of target changes.
B18: Action_Log | C18: Corrective actions / implemented changes with before–after effectiveness check.
B19: Projects | C19: Register → On-Time Delivery (#4) and Project Success Rate (#10).
B20: Cost_Schedule | C20: Monthly earned value per project → Schedule Variance (#1), Cost Variance (#2), Budget Utilization (#3).
B21: Change_Log | C21: Change requests → Scope Change Frequency (#5) and CR Approval Time (#13).
B22: Risk_Log | C22: Risk register → Risk Mitigation Effectiveness (#6).
B23: Issue_Log | C23: Issues → Issue Resolution Time (#7).
B24: Stakeholder_Survey | C24: Survey scores → Stakeholder Satisfaction (#8).
... B30: Settings | C30: Year start, current month, budget tolerance, and all drop-down lists.
B32: COLOUR CODE
B33: Yellow cell / blue text | C33: Input – type here.
B34: Grey cell / black text | C34: Formula – do not overwrite.
B35: Green text | C35: Value pulled from another sheet (e.g. targets in KPI_Tracking).
B36: GREEN / AMBER / RED | C36: Higher-is-better KPI: GREEN ≥ target, AMBER ≥ amber limit, else RED. Lower-is-better KPI: GREEN ≤ target, AMBER ≤ amber limit, else RED.
B38: BEFORE YOU USE IT FOR REAL
B39: Sample data | C39: All logs contain realistic sample data (Jan–Oct 2026) so you can see the dashboard working. Select the yellow cells in each log and press Delete – keep the grey formula columns.
B40: Dates | C40: Months in Cost_Schedule and Resources must be the 1st of the month. All logs accept ~500 rows (Projects 100).
B41: Missing data | C41: If a log has no entry for a month, that KPI shows blank (not zero) and is counted as NO DATA on the Dashboard.
B42: Charts | C42: Blank months show no bar. Add rows inside the existing ranges – formulas already cover them.
B44: KPI DESIGN CHALLENGES – read once
B45: Overlaps | C45: Budget Utilization alone is misleading: 100% of budget spent on 70% of the work looks 'perfect'. Always read it with Cost Variance (#2) – that is why both are calculated from the same EVM data.
B46: Schedule variance | C46: The picture says 'timelines'. Date-only variance hides partial progress; this workbook uses earned value (SV%) and keeps milestone dates in #11 and project finish dates in #4.
B47: Small samples | C47: On-Time Delivery and Success Rate run YTD because only a few projects finish per month. One late project can move the % by 20+ points – look at the count, not only the %.
B48: Utilisation | C48: Higher is not always better. Sustained >95% resource utilisation means no slack for breakdowns or learning; treat it as a warning, not a win.
B49: Productivity | C49: A 'Team Productivity Index' is only meaningful if each team defines one stable output unit (m drilled, t moved, WOs closed). Changing the unit mid-year breaks the trend.
B50: Continuous improvement | C50: Counting initiatives measures activity, not improvement. Use 'Benefit verified' in CI_Log and the before/after values in Action_Log to prove impact.
...

Sheet Dashboard
B1: PROJECT MANAGEMENT KPI DASHBOARD
B2: =Settings!B4 -> Mining Services – Project Portfolio
B4: Reporting month ▶ | C4: =MIN(Settings!$B$6,EDATE(Settings!$B$5,11)) -> 46296 | D4: ← select a month from the drop-down
B6: KPI status this month | C6: GREEN | E6: AMBER | G6: RED | I6: NO DATA
B7: =IF(SUM(C7:H7)=0,"",TEXT(C7/(C7+E7+G7),"0%")&" of measured KPIs on target") -> 44% of measured KPIs on target | C7: =COUNTIF($H$11:$H$26,"GREEN") -> 7 | E7: =COUNTIF($H$11:$H$26,"AMBER") -> 4 | G7: =COUNTIF($H$11:$H$26,"RED") -> 5 | I7: =COUNTBLANK($D$11:$D$26) -> 0
B10: KPI | C10: Target | D10: Actual | E10: Prev. month | F10: Change | G10: Trend | H10: Status | I10: Open actions | J10: Actions done | L10: PORTFOLIO SNAPSHOT (live)
B11: =KPI_Tracking!B5 -> Project Schedule Variance (SV%) | C11: =KPI_Tracking!E5 -> 0 | D11: =IFERROR(INDEX(KPI_Tracking!$G5:$R5,MATCH($C$4,KPI_Tracking!$G$4:$R$4,0)),"") -> -0.067027027 | E11: =IFERROR(IF(MATCH($C$4,KPI_Tracking!$G$4:$R$4,0)=1,"",INDEX(KPI_Tracking!$G5:$R5,MATCH($C$4,KPI_Tracking!$G$4:$R$4,0)-1)),"") -> -0.034266327 | F11: =IF(OR(D11="",E11=""),"",D11-E11) -> -0.0327607 | G11: =IF(F11="","",IF(F11=0,"► Stable",IF((F11>0)=(KPI_Tracking!$D5="Higher"),"▲ Better","▼ Worse"))) -> ▼ Worse | H11: =IF(D11="","",IF(KPI_Tracking!$D5="Higher",IF(D11>=KPI_Tracking!$E5,"GREEN",IF(D11>=KPI_Tracking!$F5,"AMBER","RED")),IF(D11<=KPI_Tracking!$E5,"GREEN",IF(D11<=KPI_Tracking!$F5,"AMBER","RED")))) -> RED | I11: =COUNTIFS(Action_Log!$C$5:$C$504,B11,Action_Log!$J$5:$J$504,"Open")+COUNTIFS(Action_Log!$C$5:$C$504,B11,Action_Log!$J$5:$J$504,"In progress") -> 0 | J11: =COUNTIFS(Action_Log!$C$5:$C$504,B11,Action_Log!$J$5:$J$504,"Implemented") -> 1 | L11: Projects registered | M11: =COUNTA(Projects!$A$5:$A$104) -> 8
B12: =KPI_Tracking!B6 -> Project Cost Variance (CV%) | C12: =KPI_Tracking!E6 -> 0 | D12: =IFERROR(INDEX(KPI_Tracking!$G6:$R6,MATCH($C$4,KPI_Tracking!$G$4:$R$4,0)),"") -> -0.037369641 | E12: =IFERROR(IF(MATCH($C$4,KPI_Tracking!$G$4:$R$4,0)=1,"",INDEX(KPI_Tracking!$G6:$R6,MATCH($C$4,KPI_Tracking!$G$4:$R$4,0)-1)),"") -> -0.01668716 | F12: =IF(OR(D12="",E12=""),"",D12-E12) -> -0.020682481 | G12: =IF(F12="","",IF(F12=0,"► Stable",IF((F12>0)=(KPI_Tracking!$D6="Higher"),"▲ Better","▼ Worse"))) -> ▼ Worse | H12: =IF(D12="","",IF(KPI_Tracking!$D6="Higher",IF(D12>=KPI_Tracking!$E6,"GREEN",IF(D12>=KPI_Tracking!$F6,"AMBER","RED")),IF(D12<=KPI_Tracking!$E6,"GREEN",IF(D12<=KPI_Tracking!$F6,"AMBER","RED")))) -> AMBER | I12: =COUNTIFS(Action_Log!$C$5:$C$504,B12,Action_Log!$J$5:$J$504,"Open")+COUNTIFS(Action_Log!$C$5:$C$504,B12,Action_Log!$J$5:$J$504,"In progress") -> 1 | J12: =COUNTIFS(Action_Log!$C$5:$C$504,B12,Action_Log!$J$5:$J$504,"Implemented") -> 1 | L12: Active projects | M12: =COUNTIF(Projects!$I$5:$I$104,"Active") -> 3
B13: =KPI_Tracking!B7 -> Budget Utilization | C13: =KPI_Tracking!E7 -> 1 | D13: =IFERROR(INDEX(KPI_Tracking!$G7:$R7,MATCH($C$4,KPI_Tracking!$G$4:$R$4,0)),"") -> 0.95493333 | E13: =IFERROR(IF(MATCH($C$4,KPI_Tracking!$G$4:$R$4,0)=1,"",INDEX(KPI_Tracking!$G7:$R7,MATCH($C$4,KPI_Tracking!$G$4:$R$4,0)-1)),"") -> 0.94420881 | F13: =IF(OR(D13="",E13=""),"",D13-E13) -> 0.010724524 | G13: =IF(F13="","",IF(F13=0,"► Stable",IF((F13>0)=(KPI_Tracking!$D7="Higher"),"▲ Better","▼ Worse"))) -> ▼ Worse | H13: =IF(D13="","",IF(KPI_Tracking!$D7="Higher",IF(D13>=KPI_Tracking!$E7,"GREEN",IF(D13>=KPI_Tracking!$F7,"AMBER","RED")),IF(D13<=KPI_Tracking!$E7,"GREEN",IF(D13<=KPI_Tracking!$F7,"AMBER","RED")))) -> GREEN | I13: =COUNTIFS(Action_Log!$C$5:$C$504,B13,Action_Log!$J$5:$J$504,"Open")+COUNTIFS(Action_Log!$C$5:$C$504,B13,Action_Log!$J$5:$J$504,"In progress") -> 0 | J13: =COUNTIFS(Action_Log!$C$5:$C$504,B13,Action_Log!$J$5:$J$504,"Implemented") -> 0 | L13: Completed projects | M13: =COUNTIF(Projects!$I$5:$I$104,"Completed") -> 5
B14: =KPI_Tracking!B8 -> On-Time Project Delivery | C14: =KPI_Tracking!E8 -> 0.9 | D14: =IFERROR(INDEX(KPI_Tracking!$G8:$R8,MATCH($C$4,KPI_Tracking!$G$4:$R$4,0)),"") -> 0.6 | E14: =IFERROR(IF(MATCH($C$4,KPI_Tracking!$G$4:$R$4,0)=1,"",INDEX(KPI_Tracking!$G8:$R8,MATCH($C$4,KPI_Tracking!$G$4:$R$4,0)-1)),"") -> 0.6 | F14: =IF(OR(D14="",E14=""),"",D14-E14) -> 0 | G14: =IF(F14="","",IF(F14=0,"► Stable",IF((F14>0)=(KPI_Tracking!$D8="Higher"),"▲ Better","▼ Worse"))) -> ► Stable | H14: =IF(D14="","",IF(KPI_Tracking!$D8="Higher",IF(D14>=KPI_Tracking!$E8,"GREEN",IF(D14>=KPI_Tracking!$F8,"AMBER","RED")),IF(D14<=KPI_Tracking!$E8,"GREEN",IF(D14<=KPI_Tracking!$F8,"AMBER","RED")))) -> RED | I14: =COUNTIFS(Action_Log!$C$5:$C$504,B14,Action_Log!$J$5:$J$504,"Open")+COUNTIFS(Action_Log!$C$5:$C$504,B14,Action_Log!$J$5:$J$504,"In progress") -> 0 | J14: =COUNTIFS(Action_Log!$C$5:$C$504,B14,Action_Log!$J$5:$J$504,"Implemented") -> 0 | L14: Total budget (BAC) | M14: =SUM(Projects!$J$5:$J$104) -> 13320000
B15: =KPI_Tracking!B9 -> Scope Change Frequency | C15: =KPI_Tracking!E9 -> 0.5 | D15: =IFERROR(INDEX(KPI_Tracking!$G9:$R9,MATCH($C$4,KPI_Tracking!$G$4:$R$4,0)),"") -> 0 | E15: =IFERROR(IF(MATCH($C$4,KPI_Tracking!$G$4:$R$4,0)=1,"",INDEX(KPI_Tracking!$G9:$R9,MATCH($C$4,KPI_Tracking!$G$4:$R$4,0)-1)),"") -> 0 | F15: =IF(OR(D15="",E15=""),"",D15-E15) -> 0 | G15: =IF(F15="","",IF(F15=0,"► Stable",IF((F15>0)=(KPI_Tracking!$D9="Higher"),"▲ Better","▼ Worse"))) -> ► Stable | H15: =IF(D15="","",IF(KPI_Tracking!$D9="Higher",IF(D15>=KPI_Tracking!$E9,"GREEN",IF(D15>=KPI_Tracking!$F9,"AMBER","RED")),IF(D15<=KPI_Tracking!$E9,"GREEN",IF(D15<=KPI_Tracking!$F9,"AMBER","RED")))) -> GREEN | I15: =COUNTIFS(Action_Log!$C$5:$C$504,B15,Action_Log!$J$5:$J$504,"Open")+COUNTIFS(Action_Log!$C$5:$C$504,B15,Action_Log!$J$5:$J$504,"In progress") -> 0 | J15: =COUNTIFS(Action_Log!$C$5:$C$504,B15,Action_Log!$J$5:$J$504,"Implemented") -> 1 | L15: Total forecast cost (EAC) | M15: =SUM(Projects!$K$5:$K$104) -> 13795000
B16: =KPI_Tracking!B10 -> Risk Mitigation Effectiveness | C16: =KPI_Tracking!E10 -> 0.85 | D16: =IFERROR(INDEX(KPI_Tracking!$G10:$R10,MATCH($C$4,KPI_Tracking!$G$4:$R$4,0)),"") -> 0.8125 | E16: =IFERROR(IF(MATCH($C$4,KPI_Tracking!$G$4:$R$4,0)=1,"",INDEX(KPI_Tracking!$G10:$R10,MATCH($C$4,KPI_Tracking!$G$4:$R$4,0)-1)),"") -> 0.76923077 | F16: =IF(OR(D16="",E16=""),"",D16-E16) -> 0.043269231 | G16: =IF(F16="","",IF(F16=0,"► Stable",IF((F16>0)=(KPI_Tracking!$D10="Higher"),"▲ Better","▼ Worse"))) -> ▲ Better | H16: =IF(D16="","",IF(KPI_Tracking!$D10="Higher",IF(D16>=KPI_Tracking!$E10,"GREEN",IF(D16>=KPI_Tracking!$F10,"AMBER","RED")),IF(D16<=KPI_Tracking!$E10,"GREEN",IF(D16<=KPI_Tracking!$F10,"AMBER","RED")))) -> AMBER | I16: =COUNTIFS(Action_Log!$C$5:$C$504,B16,Action_Log!$J$5:$J$504,"Open")+COUNTIFS(Action_Log!$C$5:$C$504,B16,Action_Log!$J$5:$J$504,"In progress") -> 0 | J16: =COUNTIFS(Action_Log!$C$5:$C$504,B16,Action_Log!$J$5:$J$504,"Implemented") -> 0 | L16: Forecast over(−)/under(+) budget | M16: =M14-M15 -> -475000
B17: =KPI_Tracking!B11 -> Issue Resolution Time | C17: =KPI_Tracking!E11 -> 7 | D17: =IFERROR(INDEX(KPI_Tracking!$G11:$R11,MATCH($C$4,KPI_Tracking!$G$4:$R$4,0)),"") -> 5 | E17: =IFERROR(IF(MATCH($C$4,KPI_Tracking!$G$4:$R$4,0)=1,"",INDEX(KPI_Tracking!$G11:$R11,MATCH($C$4,KPI_Tracking!$G$4:$R$4,0)-1)),"") -> 13 | F17: =IF(OR(D17="",E17=""),"",D17-E17) -> -8 | G17: =IF(F17="","",IF(F17=0,"► Stable",IF((F17>0)=(KPI_Tracking!$D11="Higher"),"▲ Better","▼ Worse"))) -> ▲ Better | H17: =IF(D17="","",IF(KPI_Tracking!$D11="Higher",IF(D17>=KPI_Tracking!$E11,"GREEN",IF(D17>=KPI_Tracking!$F11,"AMBER","RED")),IF(D17<=KPI_Tracking!$E11,"GREEN",IF(D17<=KPI_Tracking!$F11,"AMBER","RED")))) -> GREEN | I17: =COUNTIFS(Action_Log!$C$5:$C$504,B17,Action_Log!$J$5:$J$504,"Open")+COUNTIFS(Action_Log!$C$5:$C$504,B17,Action_Log!$J$5:$J$504,"In progress") -> 0 | J17: =COUNTIFS(Action_Log!$C$5:$C$504,B17,Action_Log!$J$5:$J$504,"Implemented") -> 1 | L17: Open risks | M17: =COUNTIF(Risk_Log!$L$5:$L$504,"Open") -> 12
B18: =KPI_Tracking!B12 -> Stakeholder Satisfaction | C18: =KPI_Tracking!E12 -> 4 | D18: =IFERROR(INDEX(KPI_Tracking!$G12:$R12,MATCH($C$4,KPI_Tracking!$G$4:$R$4,0)),"") -> 3.9166667 | E18: =IFERROR(IF(MATCH($C$4,KPI_Tracking!$G$4:$R$4,0)=1,"",INDEX(KPI_Tracking!$G12:$R12,MATCH($C$4,KPI_Tracking!$G$4:$R$4,0)-1)),"") -> 4.3333333 | F18: =IF(OR(D18="",E18=""),"",D18-E18) -> -0.41666667 | G18: =IF(F18="","",IF(F18=0,"► Stable",IF((F18>0)=(KPI_Tracking!$D12="Higher"),"▲ Better","▼ Worse"))) -> ▼ Worse | H18: =IF(D18="","",IF(KPI_Tracking!$D12="Higher",IF(D18>=KPI_Tracking!$E12,"GREEN",IF(D18>=KPI_Tracking!$F12,"AMBER","RED")),IF(D18<=KPI_Tracking!$E12,"GREEN",IF(D18<=KPI_Tracking!$F12,"AMBER","RED")))) -> AMBER | I18: =COUNTIFS(Action_Log!$C$5:$C$504,B18,Action_Log!$J$5:$J$504,"Open")+COUNTIFS(Action_Log!$C$5:$C$504,B18,Action_Log!$J$5:$J$504,"In progress") -> 0 | J18: =COUNTIFS(Action_Log!$C$5:$C$504,B18,Action_Log!$J$5:$J$504,"Implemented") -> 0 | L18: …of which HIGH | M18: =COUNTIFS(Risk_Log!$L$5:$L$504,"Open",Risk_Log!$I$5:$I$504,"High") -> 6
B19: =KPI_Tracking!B13 -> Resource Utilization Rate | C19: =KPI_Tracking!E13 -> 0.85 | D19: =IFERROR(INDEX(KPI_Tracking!$G13:$R13,MATCH($C$4,KPI_Tracking!$G$4:$R$4,0)),"") -> 0.86126374 | E19: =IFERROR(IF(MATCH($C$4,KPI_Tracking!$G$4:$R$4,0)=1,"",INDEX(KPI_Tracking!$G13:$R13,MATCH($C$4,KPI_Tracking!$G$4:$R$4,0)-1)),"") -> 0.84547872 | F19: =IF(OR(D19="",E19=""),"",D19-E19) -> 0.015785013 | G19: =IF(F19="","",IF(F19=0,"► Stable",IF((F19>0)=(KPI_Tracking!$D13="Higher"),"▲ Better","▼ Worse"))) -> ▲ Better | H19: =IF(D19="","",IF(KPI_Tracking!$D13="Higher",IF(D19>=KPI_Tracking!$E13,"GREEN",IF(D19>=KPI_Tracking!$F13,"AMBER","RED")),IF(D19<=KPI_Tracking!$E13,"GREEN",IF(D19<=KPI_Tracking!$F13,"AMBER","RED")))) -> GREEN | I19: =COUNTIFS(Action_Log!$C$5:$C$504,B19,Action_Log!$J$5:$J$504,"Open")+COUNTIFS(Action_Log!$C$5:$C$504,B19,Action_Log!$J$5:$J$504,"In progress") -> 1 | J19: =COUNTIFS(Action_Log!$C$5:$C$504,B19,Action_Log!$J$5:$J$504,"Implemented") -> 0 | L19: Open issues | M19: =COUNTIF(Issue_Log!$G$5:$G$504,"Open")+COUNTIF(Issue_Log!$G$5:$G$504,"In progress") -> 1
B20: =KPI_Tracking!B14 -> Project Success Rate | C20: =KPI_Tracking!E14 -> 0.8 | D20: =IFERROR(INDEX(KPI_Tracking!$G14:$R14,MATCH($C$4,KPI_Tracking!$G$4:$R$4,0)),"") -> 0.6 | E20: =IFERROR(IF(MATCH($C$4,KPI_Tracking!$G$4:$R$4,0)=1,"",INDEX(KPI_Tracking!$G14:$R14,MATCH($C$4,KPI_Tracking!$G$4:$R$4,0)-1)),"") -> 0.6 | F20: =IF(OR(D20="",E20=""),"",D20-E20) -> 0 | G20: =IF(F20="","",IF(F20=0,"► Stable",IF((F20>0)=(KPI_Tracking!$D14="Higher"),"▲ Better","▼ Worse"))) -> ► Stable | H20: =IF(D20="","",IF(KPI_Tracking!$D14="Higher",IF(D20>=KPI_Tracking!$E14,"GREEN",IF(D20>=KPI_Tracking!$F14,"AMBER","RED")),IF(D20<=KPI_Tracking!$E14,"GREEN",IF(D20<=KPI_Tracking!$F14,"AMBER","RED")))) -> RED | I20: =COUNTIFS(Action_Log!$C$5:$C$504,B20,Action_Log!$J$5:$J$504,"Open")+COUNTIFS(Action_Log!$C$5:$C$504,B20,Action_Log!$J$5:$J$504,"In progress") -> 0 | J20: =COUNTIFS(Action_Log!$C$5:$C$504,B20,Action_Log!$J$5:$J$504,"Implemented") -> 0 | L20: Issues open > 14 days | M20: =COUNTIF(Issue_Log!$J$5:$J$504,">14") -> 0
B21: =KPI_Tracking!B15 -> Milestone Completion Rate | C21: =KPI_Tracking!E15 -> 0.9 | D21: =IFERROR(INDEX(KPI_Tracking!$G15:$R15,MATCH($C$4,KPI_Tracking!$G$4:$R$4,0)),"") -> 0.25 | E21: =IFERROR(IF(MATCH($C$4,KPI_Tracking!$G$4:$R$4,0)=1,"",INDEX(KPI_Tracking!$G15:$R15,MATCH($C$4,KPI_Tracking!$G$4:$R$4,0)-1)),"") -> 1 | F21: =IF(OR(D21="",E21=""),"",D21-E21) -> -0.75 | G21: =IF(F21="","",IF(F21=0,"► Stable",IF((F21>0)=(KPI_Tracking!$D15="Higher"),"▲ Better","▼ Worse"))) -> ▼ Worse | H21: =IF(D21="","",IF(KPI_Tracking!$D15="Higher",IF(D21>=KPI_Tracking!$E15,"GREEN",IF(D21>=KPI_Tracking!$F15,"AMBER","RED")),IF(D21<=KPI_Tracking!$E15,"GREEN",IF(D21<=KPI_Tracking!$F15,"AMBER","RED")))) -> RED | I21: =COUNTIFS(Action_Log!$C$5:$C$504,B21,Action_Log!$J$5:$J$504,"Open")+COUNTIFS(Action_Log!$C$5:$C$504,B21,Action_Log!$J$5:$J$504,"In progress") -> 0 | J21: =COUNTIFS(Action_Log!$C$5:$C$504,B21,Action_Log!$J$5:$J$504,"Implemented") -> 1 | L21: Change requests pending | M21: =COUNTIF(Change_Log!$I$5:$I$504,"Pending") -> 1
B22: =KPI_Tracking!B16 -> Project Quality Index | C22: =KPI_Tracking!E16 -> 0.95 | D22: =IFERROR(INDEX(KPI_Tracking!$G16:$R16,MATCH($C$4,KPI_Tracking!$G$4:$R$4,0)),"") -> 1 | E22: =IFERROR(IF(MATCH($C$4,KPI_Tracking!$G$4:$R$4,0)=1,"",INDEX(KPI_Tracking!$G16:$R16,MATCH($C$4,KPI_Tracking!$G$4:$R$4,0)-1)),"") -> 1 | F22: =IF(OR(D22="",E22=""),"",D22-E22) -> 0 | G22: =IF(F22="","",IF(F22=0,"► Stable",IF((F22>0)=(KPI_Tracking!$D16="Higher"),"▲ Better","▼ Worse"))) -> ► Stable | H22: =IF(D22="","",IF(KPI_Tracking!$D16="Higher",IF(D22>=KPI_Tracking!$E16,"GREEN",IF(D22>=KPI_Tracking!$F16,"AMBER","RED")),IF(D22<=KPI_Tracking!$E16,"GREEN",IF(D22<=KPI_Tracking!$F16,"AMBER","RED")))) -> GREEN | I22: =COUNTIFS(Action_Log!$C$5:$C$504,B22,Action_Log!$J$5:$J$504,"Open")+COUNTIFS(Action_Log!$C$5:$C$504,B22,Action_Log!$J$5:$J$504,"In progress") -> 0 | J22: =COUNTIFS(Action_Log!$C$5:$C$504,B22,Action_Log!$J$5:$J$504,"Implemented") -> 1 | L22: Approved CR cost impact (YTD) | M22: =SUMIFS(Change_Log!$G$5:$G$504,Change_Log!$I$5:$I$504,"Approved") -> 449000
B23: =KPI_Tracking!B17 -> Change Request Approval Time | C23: =KPI_Tracking!E17 -> 5 | D23: =IFERROR(INDEX(KPI_Tracking!$G17:$R17,MATCH($C$4,KPI_Tracking!$G$4:$R$4,0)),"") -> 5 | E23: =IFERROR(IF(MATCH($C$4,KPI_Tracking!$G$4:$R$4,0)=1,"",INDEX(KPI_Tracking!$G17:$R17,MATCH($C$4,KPI_Tracking!$G$4:$R$4,0)-1)),"") -> 6.6666667 | F23: =IF(OR(D23="",E23=""),"",D23-E23) -> -1.6666667 | G23: =IF(F23="","",IF(F23=0,"► Stable",IF((F23>0)=(KPI_Tracking!$D17="Higher"),"▲ Better","▼ Worse"))) -> ▲ Better | H23: =IF(D23="","",IF(KPI_Tracking!$D17="Higher",IF(D23>=KPI_Tracking!$E17,"GREEN",IF(D23>=KPI_Tracking!$F17,"AMBER","RED")),IF(D23<=KPI_Tracking!$E17,"GREEN",IF(D23<=KPI_Tracking!$F17,"AMBER","RED")))) -> GREEN | I23: =COUNTIFS(Action_Log!$C$5:$C$504,B23,Action_Log!$J$5:$J$504,"Open")+COUNTIFS(Action_Log!$C$5:$C$504,B23,Action_Log!$J$5:$J$504,"In progress") -> 0 | J23: =COUNTIFS(Action_Log!$C$5:$C$504,B23,Action_Log!$J$5:$J$504,"Implemented") -> 1 | L23: Overdue milestones | M23: =COUNTIF(Milestones!$H$5:$H$504,"Overdue") -> 3
B24: =KPI_Tracking!B18 -> Team Productivity Index | C24: =KPI_Tracking!E18 -> 1 | D24: =IFERROR(INDEX(KPI_Tracking!$G18:$R18,MATCH($C$4,KPI_Tracking!$G$4:$R$4,0)),"") -> 0.95547917 | E24: =IFERROR(IF(MATCH($C$4,KPI_Tracking!$G$4:$R$4,0)=1,"",INDEX(KPI_Tracking!$G18:$R18,MATCH($C$4,KPI_Tracking!$G$4:$R$4,0)-1)),"") -> 0.97321528 | F24: =IF(OR(D24="",E24=""),"",D24-E24) -> -0.017736111 | G24: =IF(F24="","",IF(F24=0,"► Stable",IF((F24>0)=(KPI_Tracking!$D18="Higher"),"▲ Better","▼ Worse"))) -> ▼ Worse | H24: =IF(D24="","",IF(KPI_Tracking!$D18="Higher",IF(D24>=KPI_Tracking!$E18,"GREEN",IF(D24>=KPI_Tracking!$F18,"AMBER","RED")),IF(D24<=KPI_Tracking!$E18,"GREEN",IF(D24<=KPI_Tracking!$F18,"AMBER","RED")))) -> AMBER | I24: =COUNTIFS(Action_Log!$C$5:$C$504,B24,Action_Log!$J$5:$J$504,"Open")+COUNTIFS(Action_Log!$C$5:$C$504,B24,Action_Log!$J$5:$J$504,"In progress") -> 1 | J24: =COUNTIFS(Action_Log!$C$5:$C$504,B24,Action_Log!$J$5:$J$504,"Implemented") -> 0 | L24: Corrective actions open | M24: =COUNTIF(Action_Log!$N$5:$N$504,"On track")+COUNTIF(Action_Log!$N$5:$N$504,"OVERDUE") -> 3
B25: =KPI_Tracking!B19 -> Benefits Realization | C25: =KPI_Tracking!E19 -> 0.9 | D25: =IFERROR(INDEX(KPI_Tracking!$G19:$R19,MATCH($C$4,KPI_Tracking!$G$4:$R$4,0)),"") -> 0.92257418 | E25: =IFERROR(IF(MATCH($C$4,KPI_Tracking!$G$4:$R$4,0)=1,"",INDEX(KPI_Tracking!$G19:$R19,MATCH($C$4,KPI_Tracking!$G$4:$R$4,0)-1)),"") -> 0.86627371 | F25: =IF(OR(D25="",E25=""),"",D25-E25) -> 0.056300469 | G25: =IF(F25="","",IF(F25=0,"► Stable",IF((F25>0)=(KPI_Tracking!$D19="Higher"),"▲ Better","▼ Worse"))) -> ▲ Better | H25: =IF(D25="","",IF(KPI_Tracking!$D19="Higher",IF(D25>=KPI_Tracking!$E19,"GREEN",IF(D25>=KPI_Tracking!$F19,"AMBER","RED")),IF(D25<=KPI_Tracking!$E19,"GREEN",IF(D25<=KPI_Tracking!$F19,"AMBER","RED")))) -> GREEN | I25: =COUNTIFS(Action_Log!$C$5:$C$504,B25,Action_Log!$J$5:$J$504,"Open")+COUNTIFS(Action_Log!$C$5:$C$504,B25,Action_Log!$J$5:$J$504,"In progress") -> 0 | J25: =COUNTIFS(Action_Log!$C$5:$C$504,B25,Action_Log!$J$5:$J$504,"Implemented") -> 0 | L25: …of which OVERDUE | M25: =COUNTIF(Action_Log!$N$5:$N$504,"OVERDUE") -> 2
B26: =KPI_Tracking!B20 -> Continuous Improvement Initiatives | C26: =KPI_Tracking!E20 -> 2 | D26: =IFERROR(INDEX(KPI_Tracking!$G20:$R20,MATCH($C$4,KPI_Tracking!$G$4:$R$4,0)),"") -> 0 | E26: =IFERROR(IF(MATCH($C$4,KPI_Tracking!$G$4:$R$4,0)=1,"",INDEX(KPI_Tracking!$G20:$R20,MATCH($C$4,KPI_Tracking!$G$4:$R$4,0)-1)),"") -> 0 | F26: =IF(OR(D26="",E26=""),"",D26-E26) -> 0 | G26: =IF(F26="","",IF(F26=0,"► Stable",IF((F26>0)=(KPI_Tracking!$D20="Higher"),"▲ Better","▼ Worse"))) -> ► Stable | H26: =IF(D26="","",IF(KPI_Tracking!$D20="Higher",IF(D26>=KPI_Tracking!$E20,"GREEN",IF(D26>=KPI_Tracking!$F20,"AMBER","RED")),IF(D26<=KPI_Tracking!$E20,"GREEN",IF(D26<=KPI_Tracking!$F20,"AMBER","RED")))) -> RED | I26: =COUNTIFS(Action_Log!$C$5:$C$504,B26,Action_Log!$J$5:$J$504,"Open")+COUNTIFS(Action_Log!$C$5:$C$504,B26,Action_Log!$J$5:$J$504,"In progress") -> 0 | J26: =COUNTIFS(Action_Log!$C$5:$C$504,B26,Action_Log!$J$5:$J$504,"Implemented") -> 0 | L26: Actions that improved the KPI | M26: =IFERROR(COUNTIF(Action_Log!$M$5:$M$504,"Improved")/COUNTA(Action_Log!$L$5:$L$504),"") -> 1
L27: CI initiatives implemented (YTD) | M27: =COUNTIF(CI_Log!$F$5:$F$504,"Implemented") -> 11
L28: …with benefit verified | M28: =COUNTIFS(CI_Log!$F$5:$F$504,"Implemented",CI_Log!$I$5:$I$504,"Yes") -> 10
L29: Target revisions logged | M29: =COUNT(Target_Revisions!$B$5:$B$104) -> 2
B31: TRENDS – key KPIs (all 16 charts on the Trends sheet)

Sheet KPI_Tracking
A1: KPI Tracking – Monthly Actual vs Target
A2: Fully automatic: actuals are calculated from the logs. Months after the current reporting month (Settings) stay blank. Targets come from KPI_Targets.
A4: # | B4: KPI | C4: Unit | D4: Direction | E4: Target | F4: Amber limit | G4: =EDATE(Settings!$B$5,0) -> 46023 | H4: =EDATE(Settings!$B$5,1) -> 46054 | I4: =EDATE(Settings!$B$5,2) -> 46082 | J4: =EDATE(Settings!$B$5,3) -> 46113 | K4: =EDATE(Settings!$B$5,4) -> 46143 | L4: =EDATE(Settings!$B$5,5) -> 46174 | M4: =EDATE(Settings!$B$5,6) -> 46204 | N4: =EDATE(Settings!$B$5,7) -> 46235 | O4: =EDATE(Settings!$B$5,8) -> 46266 | P4: =EDATE(Settings!$B$5,9) -> 46296 | Q4: =EDATE(Settings!$B$5,10) -> 46327 | R4: =EDATE(Settings!$B$5,11) -> 46357 | S4: Latest actual | T4: Latest status | U4: Months GREEN | V4: Months RED
A5: 1 | B5: =KPI_Targets!B5 -> Project Schedule Variance (SV%) | C5: =KPI_Targets!E5 -> % | D5: =KPI_Targets!F5 -> Higher | E5: =KPI_Targets!G5 -> 0 | F5: =KPI_Targets!H5 -> -0.05 | G5: =IF(G$4>Settings!$B$6,"",IFERROR((SUMIFS(Cost_Schedule!$F$5:$F$504,Cost_Schedule!$A$5:$A$504,">="&G$4,Cost_Schedule!$A$5:$A$504,"<="&EOMONTH(G$4,0))-SUMIFS(Cost_Schedule!$E$5:$E$504,Cost_Schedule!$A$5:$A$504,">="&G$4,Cost_Schedule!$A$5:$A$504,"<="&EOMONTH(G$4,0)))/SUMIFS(Cost_Schedule!$E$5:$E$504,Cost_Schedule!$A$5:$A$504,">="&G$4,Cost_Schedule!$A$5:$A$504,"<="&EOMONTH(G$4,0)),"")) -> -0.053607374 | H5: =IF(H$4>Settings!$B$6,"",IFERROR((SUMIFS(Cost_Schedule!$F$5:$F$504,Cost_Schedule!$A$5:$A$504,">="&H$4,Cost_Schedule!$A$5:$A$504,"<="&EOMONTH(H$4,0))-SUMIFS(Cost_Schedule!$E$5:$E$504,Cost_Schedule!$A$5:$A$504,">="&H$4,Cost_Schedule!$A$5:$A$504,"<="&EOMONTH(H$4,0)))/SUMIFS(Cost_Schedule!$E$5:$E$504,Cost_Schedule!$A$5:$A$504,">="&H$4,Cost_Schedule!$A$5:$A$504,"<="&EOMONTH(H$4,0)),"")) -> -0.032187819 | I5: =IF(I$4>Settings!$B$6,"",IFERROR((SUMIFS(Cost_Schedule!$F$5:$F$504,Cost_Schedule!$A$5:$A$504,">="&I$4,Cost_Schedule!$A$5:$A$504,"<="&EOMONTH(I$4,0))-SUMIFS(Cost_Schedule!$E$5:$E$504,Cost_Schedule!$A$5:$A$504,">="&I$4,Cost_Schedule!$A$5:$A$504,"<="&EOMONTH(I$4,0)))/SUMIFS(Cost_Schedule!$E$5:$E$504,Cost_Schedule!$A$5:$A$504,">="&I$4,Cost_Schedule!$A$5:$A$504,"<="&EOMONTH(I$4,0)),"")) -> -0.046944949 | J5: =IF(J$4>Settings!$B$6,"",IFERROR((SUMIFS(Cost_Schedule!$F$5:$F$504,Cost_Schedule!$A$5:$A$504,">="&J$4,Cost_Schedule!$A$5:$A$504,"<="&EOMONTH(J$4,0))-SUMIFS(Cost_Schedule!$E$5:$E$504,Cost_Schedule!$A$5:$A$504,">="&J$4,Cost_Schedule!$A$5:$A$504,"<="&EOMONTH(J$4,0)))/SUMIFS(Cost_Schedule!$E$5:$E$504,Cost_Schedule!$A$5:$A$504,">="&J$4,Cost_Schedule!$A$5:$A$504,"<="&EOMONTH(J$4,0)),"")) -> -0.031599813 | K5: =IF(K$4>Settings!$B$6,"",IFERROR((SUMIFS(Cost_Schedule!$F$5:$F$504,Cost_Schedule!$A$5:$A$504,">="&K$4,Cost_Schedule!$A$5:$A$504,"<="&EOMONTH(K$4,0))-SUMIFS(Cost_Schedule!$E$5:$E$504,Cost_Schedule!$A$5:$A$504,">="&K$4,Cost_Schedule!$A$5:$A$504,"<="&EOMONTH(K$4,0)))/SUMIFS(Cost_Schedule!$E$5:$E$504,Cost_Schedule!$A$5:$A$504,">="&K$4,Cost_Schedule!$A$5:$A$504,"<="&EOMONTH(K$4,0)),"")) -> -0.040722517 | L5: =IF(L$4>Settings!$B$6,"",IFERROR((SUMIFS(Cost_Schedule!$F$5:$F$504,Cost_Schedule!$A$5:$A$504,">="&L$4,Cost_Schedule!$A$5:$A$504,"<="&EOMONTH(L$4,0))-SUMIFS(Cost_Schedule!$E$5:$E$504,Cost_Schedule!$A$5:$A$504,">="&L$4,Cost_Schedule!$A$5:$A$504,"<="&EOMONTH(L$4,0)))/SUMIFS(Cost_Schedule!$E$5:$E$504,Cost_Schedule!$A$5:$A$504,">="&L$4,Cost_Schedule!$A$5:$A$504,"<="&EOMONTH(L$4,0)),"")) -> -0.056735279 | M5: =IF(M$4>Settings!$B$6,"",IFERROR((SUMIFS(Cost_Schedule!$F$5:$F$504,Cost_Schedule!$A$5:$A$504,">="&M$4,Cost_Schedule!$A$5:$A$504,"<="&EOMONTH(M$4,0))-SUMIFS(Cost_Schedule!$E$5:$E$504,Cost_Schedule!$A$5:$A$504,">="&M$4,Cost_Schedule!$A$5:$A$504,"<="&EOMONTH(M$4,0)))/SUMIFS(Cost_Schedule!$E$5:$E$504,Cost_Schedule!$A$5:$A$504,">="&M$4,Cost_Schedule!$A$5:$A$504,"<="&EOMONTH(M$4,0)),"")) -> -0.053169038 | N5: =IF(N$4>Settings!$B$6,"",IFERROR((SUMIFS(Cost_Schedule!$F$5:$F$504,Cost_Schedule!$A$5:$A$504,">="&N$4,Cost_Schedule!$A$5:$A$504,"<="&EOMONTH(N$4,0))-SUMIFS(Cost_Schedule!$E$5:$E$504,Cost_Schedule!$A$5:$A$504,">="&N$4,Cost_Schedule!$A$5:$A$504,"<="&EOMONTH(N$4,0)))/SUMIFS(Cost_Schedule!$E$5:$E$504,Cost_Schedule!$A$5:$A$504,">="&N$4,Cost_Schedule!$A$5:$A$504,"<="&EOMONTH(N$4,0)),"")) -> -0.038984384 | ... R5: =IF(R$4>Settings!$B$6,"",IFERROR((SUMIFS(Cost_Schedule!$F$5:$F$504,Cost_Schedule!$A$5:$A$504,">="&R$4,Cost_Schedule!$A$5:$A$504,"<="&EOMONTH(R$4,0))-SUMIFS(Cost_Schedule!$E$5:$E$504,Cost_Schedule!$A$5:$A$504,">="&R$4,Cost_Schedule!$A$5:$A$504,"<="&EOMONTH(R$4,0)))/SUMIFS(Cost_Schedule!$E$5:$E$504,Cost_Schedule!$A$5:$A$504,">="&R$4,Cost_Schedule!$A$5:$A$504,"<="&EOMONTH(R$4,0)),"")) | S5: =IFERROR(LOOKUP(2,1/(G5:R5<>""),G5:R5),"") -> -0.067027027 | T5: =IF(S5="","",IF($D5="Higher",IF(S5>=$E5,"GREEN",IF(S5>=$F5,"AMBER","RED")),IF(S5<=$E5,"GREEN",IF(S5<=$F5,"AMBER","RED")))) -> RED | U5: =COUNTIF(G24:R24,"GREEN") -> 0 | V5: =COUNTIF(G24:R24,"RED") -> 4
A6: 2 | B6: =KPI_Targets!B6 -> Project Cost Variance (CV%) | C6: =KPI_Targets!E6 -> % | D6: =KPI_Targets!F6 -> Higher | E6: =KPI_Targets!G6 -> 0 | F6: =KPI_Targets!H6 -> -0.05 | G6: =IF(G$4>Settings!$B$6,"",IFERROR((SUMIFS(Cost_Schedule!$F$5:$F$504,Cost_Schedule!$A$5:$A$504,">="&G$4,Cost_Schedule!$A$5:$A$504,"<="&EOMONTH(G$4,0))-SUMIFS(Cost_Schedule!$G$5:$G$504,Cost_Schedule!$A$5:$A$504,">="&G$4,Cost_Schedule!$A$5:$A$504,"<="&EOMONTH(G$4,0)))/SUMIFS(Cost_Schedule!$F$5:$F$504,Cost_Schedule!$A$5:$A$504,">="&G$4,Cost_Schedule!$A$5:$A$504,"<="&EOMONTH(G$4,0)),"")) -> -0.024291951 | H6: =IF(H$4>Settings!$B$6,"",IFERROR((SUMIFS(Cost_Schedule!$F$5:$F$504,Cost_Schedule!$A$5:$A$504,">="&H$4,Cost_Schedule!$A$5:$A$504,"<="&EOMONTH(H$4,0))-SUMIFS(Cost_Schedule!$G$5:$G$504,Cost_Schedule!$A$5:$A$504,">="&H$4,Cost_Schedule!$A$5:$A$504,"<="&EOMONTH(H$4,0)))/SUMIFS(Cost_Schedule!$F$5:$F$504,Cost_Schedule!$A$5:$A$504,">="&H$4,Cost_Schedule!$A$5:$A$504,"<="&EOMONTH(H$4,0)),"")) -> -0.0088595134 | I6: =IF(I$4>Settings!$B$6,"",IFERROR((SUMIFS(Cost_Schedule!$F$5:$F$504,Cost_Schedule!$A$5:$A$504,">="&I$4,Cost_Schedule!$A$5:$A$504,"<="&EOMONTH(I$4,0))-SUMIFS(Cost_Schedule!$G$5:$G$504,Cost_Schedule!$A$5:$A$504,">="&I$4,Cost_Schedule!$A$5:$A$504,"<="&EOMONTH(I$4,0)))/SUMIFS(Cost_Schedule!$F$5:$F$504,Cost_Schedule!$A$5:$A$504,">="&I$4,Cost_Schedule!$A$5:$A$504,"<="&EOMONTH(I$4,0)),"")) -> -0.017963692 | J6: =IF(J$4>Settings!$B$6,"",IFERROR((SUMIFS(Cost_Schedule!$F$5:$F$504,Cost_Schedule!$A$5:$A$504,">="&J$4,Cost_Schedule!$A$5:$A$504,"<="&EOMONTH(J$4,0))-SUMIFS(Cost_Schedule!$G$5:$G$504,Cost_Schedule!$A$5:$A$504,">="&J$4,Cost_Schedule!$A$5:$A$504,"<="&EOMONTH(J$4,0)))/SUMIFS(Cost_Schedule!$F$5:$F$504,Cost_Schedule!$A$5:$A$504,">="&J$4,Cost_Schedule!$A$5:$A$504,"<="&EOMONTH(J$4,0)),"")) -> -0.02667068 | K6: =IF(K$4>Settings!$B$6,"",IFERROR((SUMIFS(Cost_Schedule!$F$5:$F$504,Cost_Schedule!$A$5:$A$504,">="&K$4,Cost_Schedule!$A$5:$A$504,"<="&EOMONTH(K$4,0))-SUMIFS(Cost_Schedule!$G$5:$G$504,Cost_Schedule!$A$5:$A$504,">="&K$4,Cost_Schedule!$A$5:$A$504,"<="&EOMONTH(K$4,0)))/SUMIFS(Cost_Schedule!$F$5:$F$504,Cost_Schedule!$A$5:$A$504,">="&K$4,Cost_Schedule!$A$5:$A$504,"<="&EOMONTH(K$4,0)),"")) -> -0.040696497 | L6: =IF(L$4>Settings!$B$6,"",IFERROR((SUMIFS(Cost_Schedule!$F$5:$F$504,Cost_Schedule!$A$5:$A$504,">="&L$4,Cost_Schedule!$A$5:$A$504,"<="&EOMONTH(L$4,0))-SUMIFS(Cost_Schedule!$G$5:$G$504,Cost_Schedule!$A$5:$A$504,">="&L$4,Cost_Schedule!$A$5:$A$504,"<="&EOMONTH(L$4,0)))/SUMIFS(Cost_Schedule!$F$5:$F$504,Cost_Schedule!$A$5:$A$504,">="&L$4,Cost_Schedule!$A$5:$A$504,"<="&EOMONTH(L$4,0)),"")) -> -0.034804226 | M6: =IF(M$4>Settings!$B$6,"",IFERROR((SUMIFS(Cost_Schedule!$F$5:$F$504,Cost_Schedule!$A$5:$A$504,">="&M$4,Cost_Schedule!$A$5:$A$504,"<="&EOMONTH(M$4,0))-SUMIFS(Cost_Schedule!$G$5:$G$504,Cost_Schedule!$A$5:$A$504,">="&M$4,Cost_Schedule!$A$5:$A$504,"<="&EOMONTH(M$4,0)))/SUMIFS(Cost_Schedule!$F$5:$F$504,Cost_Schedule!$A$5:$A$504,">="&M$4,Cost_Schedule!$A$5:$A$504,"<="&EOMONTH(M$4,0)),"")) -> -0.044434858 | N6: =IF(N$4>Settings!$B$6,"",IFERROR((SUMIFS(Cost_Schedule!$F$5:$F$504,Cost_Schedule!$A$5:$A$504,">="&N$4,Cost_Schedule!$A$5:$A$504,"<="&EOMONTH(N$4,0))-SUMIFS(Cost_Schedule!$G$5:$G$504,Cost_Schedule!$A$5:$A$504,">="&N$4,Cost_Schedule!$A$5:$A$504,"<="&EOMONTH(N$4,0)))/SUMIFS(Cost_Schedule!$F$5:$F$504,Cost_Schedule!$A$5:$A$504,">="&N$4,Cost_Schedule!$A$5:$A$504,"<="&EOMONTH(N$4,0)),"")) -> -0.0060790274 | ... R6: =IF(R$4>Settings!$B$6,"",IFERROR((SUMIFS(Cost_Schedule!$F$5:$F$504,Cost_Schedule!$A$5:$A$504,">="&R$4,Cost_Schedule!$A$5:$A$504,"<="&EOMONTH(R$4,0))-SUMIFS(Cost_Schedule!$G$5:$G$504,Cost_Schedule!$A$5:$A$504,">="&R$4,Cost_Schedule!$A$5:$A$504,"<="&EOMONTH(R$4,0)))/SUMIFS(Cost_Schedule!$F$5:$F$504,Cost_Schedule!$A$5:$A$504,">="&R$4,Cost_Schedule!$A$5:$A$504,"<="&EOMONTH(R$4,0)),"")) | S6: =IFERROR(LOOKUP(2,1/(G6:R6<>""),G6:R6),"") -> -0.037369641 | T6: =IF(S6="","",IF($D6="Higher",IF(S6>=$E6,"GREEN",IF(S6>=$F6,"AMBER","RED")),IF(S6<=$E6,"GREEN",IF(S6<=$F6,"AMBER","RED")))) -> AMBER | U6: =COUNTIF(G25:R25,"GREEN") -> 0 | V6: =COUNTIF(G25:R25,"RED") -> 0
A7: 3 | B7: =KPI_Targets!B7 -> Budget Utilization | C7: =KPI_Targets!E7 -> % | D7: =KPI_Targets!F7 -> Lower | E7: =KPI_Targets!G7 -> 1 | F7: =KPI_Targets!H7 -> 1.05 | G7: =IF(G$4>Settings!$B$6,"",IFERROR(SUMIFS(Cost_Schedule!$G$5:$G$504,Cost_Schedule!$A$5:$A$504,">="&G$4,Cost_Schedule!$A$5:$A$504,"<="&EOMONTH(G$4,0))/SUMIFS(Cost_Schedule!$D$5:$D$504,Cost_Schedule!$A$5:$A$504,">="&G$4,Cost_Schedule!$A$5:$A$504,"<="&EOMONTH(G$4,0)),"")) -> 0.93177189 | H7: =IF(H$4>Settings!$B$6,"",IFERROR(SUMIFS(Cost_Schedule!$G$5:$G$504,Cost_Schedule!$A$5:$A$504,">="&H$4,Cost_Schedule!$A$5:$A$504,"<="&EOMONTH(H$4,0))/SUMIFS(Cost_Schedule!$D$5:$D$504,Cost_Schedule!$A$5:$A$504,">="&H$4,Cost_Schedule!$A$5:$A$504,"<="&EOMONTH(H$4,0)),"")) -> 0.94394737 | I7: =IF(I$4>Settings!$B$6,"",IFERROR(SUMIFS(Cost_Schedule!$G$5:$G$504,Cost_Schedule!$A$5:$A$504,">="&I$4,Cost_Schedule!$A$5:$A$504,"<="&EOMONTH(I$4,0))/SUMIFS(Cost_Schedule!$D$5:$D$504,Cost_Schedule!$A$5:$A$504,">="&I$4,Cost_Schedule!$A$5:$A$504,"<="&EOMONTH(I$4,0)),"")) -> 0.94446408 | J7: =IF(J$4>Settings!$B$6,"",IFERROR(SUMIFS(Cost_Schedule!$G$5:$G$504,Cost_Schedule!$A$5:$A$504,">="&J$4,Cost_Schedule!$A$5:$A$504,"<="&EOMONTH(J$4,0))/SUMIFS(Cost_Schedule!$D$5:$D$504,Cost_Schedule!$A$5:$A$504,">="&J$4,Cost_Schedule!$A$5:$A$504,"<="&EOMONTH(J$4,0)),"")) -> 0.97724928 | K7: =IF(K$4>Settings!$B$6,"",IFERROR(SUMIFS(Cost_Schedule!$G$5:$G$504,Cost_Schedule!$A$5:$A$504,">="&K$4,Cost_Schedule!$A$5:$A$504,"<="&EOMONTH(K$4,0))/SUMIFS(Cost_Schedule!$D$5:$D$504,Cost_Schedule!$A$5:$A$504,">="&K$4,Cost_Schedule!$A$5:$A$504,"<="&EOMONTH(K$4,0)),"")) -> 0.97409981 | L7: =IF(L$4>Settings!$B$6,"",IFERROR(SUMIFS(Cost_Schedule!$G$5:$G$504,Cost_Schedule!$A$5:$A$504,">="&L$4,Cost_Schedule!$A$5:$A$504,"<="&EOMONTH(L$4,0))/SUMIFS(Cost_Schedule!$D$5:$D$504,Cost_Schedule!$A$5:$A$504,">="&L$4,Cost_Schedule!$A$5:$A$504,"<="&EOMONTH(L$4,0)),"")) -> 0.94662034 | M7: =IF(M$4>Settings!$B$6,"",IFERROR(SUMIFS(Cost_Schedule!$G$5:$G$504,Cost_Schedule!$A$5:$A$504,">="&M$4,Cost_Schedule!$A$5:$A$504,"<="&EOMONTH(M$4,0))/SUMIFS(Cost_Schedule!$D$5:$D$504,Cost_Schedule!$A$5:$A$504,">="&M$4,Cost_Schedule!$A$5:$A$504,"<="&EOMONTH(M$4,0)),"")) -> 0.96007931 | N7: =IF(N$4>Settings!$B$6,"",IFERROR(SUMIFS(Cost_Schedule!$G$5:$G$504,Cost_Schedule!$A$5:$A$504,">="&N$4,Cost_Schedule!$A$5:$A$504,"<="&EOMONTH(N$4,0))/SUMIFS(Cost_Schedule!$D$5:$D$504,Cost_Schedule!$A$5:$A$504,">="&N$4,Cost_Schedule!$A$5:$A$504,"<="&EOMONTH(N$4,0)),"")) -> 0.94260679 | ... R7: =IF(R$4>Settings!$B$6,"",IFERROR(SUMIFS(Cost_Schedule!$G$5:$G$504,Cost_Schedule!$A$5:$A$504,">="&R$4,Cost_Schedule!$A$5:$A$504,"<="&EOMONTH(R$4,0))/SUMIFS(Cost_Schedule!$D$5:$D$504,Cost_Schedule!$A$5:$A$504,">="&R$4,Cost_Schedule!$A$5:$A$504,"<="&EOMONTH(R$4,0)),"")) | S7: =IFERROR(LOOKUP(2,1/(G7:R7<>""),G7:R7),"") -> 0.95493333 | T7: =IF(S7="","",IF($D7="Higher",IF(S7>=$E7,"GREEN",IF(S7>=$F7,"AMBER","RED")),IF(S7<=$E7,"GREEN",IF(S7<=$F7,"AMBER","RED")))) -> GREEN | U7: =COUNTIF(G26:R26,"GREEN") -> 10 | V7: =COUNTIF(G26:R26,"RED") -> 0
A8: 4 | B8: =KPI_Targets!B8 -> On-Time Project Delivery | C8: =KPI_Targets!E8 -> % | D8: =KPI_Targets!F8 -> Higher | E8: =KPI_Targets!G8 -> 0.9 | F8: =KPI_Targets!H8 -> 0.8 | G8: =IF(G$4>Settings!$B$6,"",IFERROR(COUNTIFS(Projects!$I$5:$I$104,"Completed",Projects!$H$5:$H$104,">="&Settings!$B$5,Projects!$H$5:$H$104,"<="&EOMONTH(G$4,0),Projects!$N$5:$N$104,"Yes")/COUNTIFS(Projects!$I$5:$I$104,"Completed",Projects!$H$5:$H$104,">="&Settings!$B$5,Projects!$H$5:$H$104,"<="&EOMONTH(G$4,0)),"")) | H8: =IF(H$4>Settings!$B$6,"",IFERROR(COUNTIFS(Projects!$I$5:$I$104,"Completed",Projects!$H$5:$H$104,">="&Settings!$B$5,Projects!$H$5:$H$104,"<="&EOMONTH(H$4,0),Projects!$N$5:$N$104,"Yes")/COUNTIFS(Projects!$I$5:$I$104,"Completed",Projects!$H$5:$H$104,">="&Settings!$B$5,Projects!$H$5:$H$104,"<="&EOMONTH(H$4,0)),"")) | I8: =IF(I$4>Settings!$B$6,"",IFERROR(COUNTIFS(Projects!$I$5:$I$104,"Completed",Projects!$H$5:$H$104,">="&Settings!$B$5,Projects!$H$5:$H$104,"<="&EOMONTH(I$4,0),Projects!$N$5:$N$104,"Yes")/COUNTIFS(Projects!$I$5:$I$104,"Completed",Projects!$H$5:$H$104,">="&Settings!$B$5,Projects!$H$5:$H$104,"<="&EOMONTH(I$4,0)),"")) | J8: =IF(J$4>Settings!$B$6,"",IFERROR(COUNTIFS(Projects!$I$5:$I$104,"Completed",Projects!$H$5:$H$104,">="&Settings!$B$5,Projects!$H$5:$H$104,"<="&EOMONTH(J$4,0),Projects!$N$5:$N$104,"Yes")/COUNTIFS(Projects!$I$5:$I$104,"Completed",Projects!$H$5:$H$104,">="&Settings!$B$5,Projects!$H$5:$H$104,"<="&EOMONTH(J$4,0)),"")) -> 1 | K8: =IF(K$4>Settings!$B$6,"",IFERROR(COUNTIFS(Projects!$I$5:$I$104,"Completed",Projects!$H$5:$H$104,">="&Settings!$B$5,Projects!$H$5:$H$104,"<="&EOMONTH(K$4,0),Projects!$N$5:$N$104,"Yes")/COUNTIFS(Projects!$I$5:$I$104,"Completed",Projects!$H$5:$H$104,">="&Settings!$B$5,Projects!$H$5:$H$104,"<="&EOMONTH(K$4,0)),"")) -> 1 | L8: =IF(L$4>Settings!$B$6,"",IFERROR(COUNTIFS(Projects!$I$5:$I$104,"Completed",Projects!$H$5:$H$104,">="&Settings!$B$5,Projects!$H$5:$H$104,"<="&EOMONTH(L$4,0),Projects!$N$5:$N$104,"Yes")/COUNTIFS(Projects!$I$5:$I$104,"Completed",Projects!$H$5:$H$104,">="&Settings!$B$5,Projects!$H$5:$H$104,"<="&EOMONTH(L$4,0)),"")) -> 0.5 | M8: =IF(M$4>Settings!$B$6,"",IFERROR(COUNTIFS(Projects!$I$5:$I$104,"Completed",Projects!$H$5:$H$104,">="&Settings!$B$5,Projects!$H$5:$H$104,"<="&EOMONTH(M$4,0),Projects!$N$5:$N$104,"Yes")/COUNTIFS(Projects!$I$5:$I$104,"Completed",Projects!$H$5:$H$104,">="&Settings!$B$5,Projects!$H$5:$H$104,"<="&EOMONTH(M$4,0)),"")) -> 0.33333333 | N8: =IF(N$4>Settings!$B$6,"",IFERROR(COUNTIFS(Projects!$I$5:$I$104,"Completed",Projects!$H$5:$H$104,">="&Settings!$B$5,Projects!$H$5:$H$104,"<="&EOMONTH(N$4,0),Projects!$N$5:$N$104,"Yes")/COUNTIFS(Projects!$I$5:$I$104,"Completed",Projects!$H$5:$H$104,">="&Settings!$B$5,Projects!$H$5:$H$104,"<="&EOMONTH(N$4,0)),"")) -> 0.5 | ... R8: =IF(R$4>Settings!$B$6,"",IFERROR(COUNTIFS(Projects!$I$5:$I$104,"Completed",Projects!$H$5:$H$104,">="&Settings!$B$5,Projects!$H$5:$H$104,"<="&EOMONTH(R$4,0),Projects!$N$5:$N$104,"Yes")/COUNTIFS(Projects!$I$5:$I$104,"Completed",Projects!$H$5:$H$104,">="&Settings!$B$5,Projects!$H$5:$H$104,"<="&EOMONTH(R$4,0)),"")) | S8: =IFERROR(LOOKUP(2,1/(G8:R8<>""),G8:R8),"") -> 0.6 | T8: =IF(S8="","",IF($D8="Higher",IF(S8>=$E8,"GREEN",IF(S8>=$F8,"AMBER","RED")),IF(S8<=$E8,"GREEN",IF(S8<=$F8,"AMBER","RED")))) -> RED | U8: =COUNTIF(G27:R27,"GREEN") -> 2 | V8: =COUNTIF(G27:R27,"RED") -> 5
A9: 5 | B9: =KPI_Targets!B9 -> Scope Change Frequency | C9: =KPI_Targets!E9 -> CRs / project | D9: =KPI_Targets!F9 -> Lower | E9: =KPI_Targets!G9 -> 0.5 | F9: =KPI_Targets!H9 -> 1 | G9: =IF(G$4>Settings!$B$6,"",IFERROR(COUNTIFS(Change_Log!$E$5:$E$504,"Scope",Change_Log!$C$5:$C$504,">="&G$4,Change_Log!$C$5:$C$504,"<="&EOMONTH(G$4,0))/COUNTIFS(Projects!$F$5:$F$104,"<="&EOMONTH(G$4,0),Projects!$H$5:$H$104,">="&G$4),"")) -> 1 | H9: =IF(H$4>Settings!$B$6,"",IFERROR(COUNTIFS(Change_Log!$E$5:$E$504,"Scope",Change_Log!$C$5:$C$504,">="&H$4,Change_Log!$C$5:$C$504,"<="&EOMONTH(H$4,0))/COUNTIFS(Projects!$F$5:$F$104,"<="&EOMONTH(H$4,0),Projects!$H$5:$H$104,">="&H$4),"")) -> 0.4 | I9: =IF(I$4>Settings!$B$6,"",IFERROR(COUNTIFS(Change_Log!$E$5:$E$504,"Scope",Change_Log!$C$5:$C$504,">="&I$4,Change_Log!$C$5:$C$504,"<="&EOMONTH(I$4,0))/COUNTIFS(Projects!$F$5:$F$104,"<="&EOMONTH(I$4,0),Projects!$H$5:$H$104,">="&I$4),"")) -> 0 | J9: =IF(J$4>Settings!$B$6,"",IFERROR(COUNTIFS(Change_Log!$E$5:$E$504,"Scope",Change_Log!$C$5:$C$504,">="&J$4,Change_Log!$C$5:$C$504,"<="&EOMONTH(J$4,0))/COUNTIFS(Projects!$F$5:$F$104,"<="&EOMONTH(J$4,0),Projects!$H$5:$H$104,">="&J$4),"")) -> 0.28571429 | K9: =IF(K$4>Settings!$B$6,"",IFERROR(COUNTIFS(Change_Log!$E$5:$E$504,"Scope",Change_Log!$C$5:$C$504,">="&K$4,Change_Log!$C$5:$C$504,"<="&EOMONTH(K$4,0))/COUNTIFS(Projects!$F$5:$F$104,"<="&EOMONTH(K$4,0),Projects!$H$5:$H$104,">="&K$4),"")) -> 0.42857143 | L9: =IF(L$4>Settings!$B$6,"",IFERROR(COUNTIFS(Change_Log!$E$5:$E$504,"Scope",Change_Log!$C$5:$C$504,">="&L$4,Change_Log!$C$5:$C$504,"<="&EOMONTH(L$4,0))/COUNTIFS(Projects!$F$5:$F$104,"<="&EOMONTH(L$4,0),Projects!$H$5:$H$104,">="&L$4),"")) -> 0.14285714 | M9: =IF(M$4>Settings!$B$6,"",IFERROR(COUNTIFS(Change_Log!$E$5:$E$504,"Scope",Change_Log!$C$5:$C$504,">="&M$4,Change_Log!$C$5:$C$504,"<="&EOMONTH(M$4,0))/COUNTIFS(Projects!$F$5:$F$104,"<="&EOMONTH(M$4,0),Projects!$H$5:$H$104,">="&M$4),"")) -> 0.16666667 | N9: =IF(N$4>Settings!$B$6,"",IFERROR(COUNTIFS(Change_Log!$E$5:$E$504,"Scope",Change_Log!$C$5:$C$504,">="&N$4,Change_Log!$C$5:$C$504,"<="&EOMONTH(N$4,0))/COUNTIFS(Projects!$F$5:$F$104,"<="&EOMONTH(N$4,0),Projects!$H$5:$H$104,">="&N$4),"")) -> 0 | ... R9: =IF(R$4>Settings!$B$6,"",IFERROR(COUNTIFS(Change_Log!$E$5:$E$504,"Scope",Change_Log!$C$5:$C$504,">="&R$4,Change_Log!$C$5:$C$504,"<="&EOMONTH(R$4,0))/COUNTIFS(Projects!$F$5:$F$104,"<="&EOMONTH(R$4,0),Projects!$H$5:$H$104,">="&R$4),"")) | S9: =IFERROR(LOOKUP(2,1/(G9:R9<>""),G9:R9),"") -> 0 | T9: =IF(S9="","",IF($D9="Higher",IF(S9>=$E9,"GREEN",IF(S9>=$F9,"AMBER","RED")),IF(S9<=$E9,"GREEN",IF(S9<=$F9,"AMBER","RED")))) -> GREEN | U9: =COUNTIF(G28:R28,"GREEN") -> 9 | V9: =COUNTIF(G28:R28,"RED") -> 0
A10: 6 | B10: =KPI_Targets!B10 -> Risk Mitigation Effectiveness | C10: =KPI_Targets!E10 -> % | D10: =KPI_Targets!F10 -> Higher | E10: =KPI_Targets!G10 -> 0.85 | F10: =KPI_Targets!H10 -> 0.7 | G10: =IF(G$4>Settings!$B$6,"",IFERROR(COUNTIFS(Risk_Log!$M$5:$M$504,">="&Settings!$B$5,Risk_Log!$M$5:$M$504,"<="&EOMONTH(G$4,0),Risk_Log!$N$5:$N$504,"No")/COUNTIFS(Risk_Log!$M$5:$M$504,">="&Settings!$B$5,Risk_Log!$M$5:$M$504,"<="&EOMONTH(G$4,0)),"")) | H10: =IF(H$4>Settings!$B$6,"",IFERROR(COUNTIFS(Risk_Log!$M$5:$M$504,">="&Settings!$B$5,Risk_Log!$M$5:$M$504,"<="&EOMONTH(H$4,0),Risk_Log!$N$5:$N$504,"No")/COUNTIFS(Risk_Log!$M$5:$M$504,">="&Settings!$B$5,Risk_Log!$M$5:$M$504,"<="&EOMONTH(H$4,0)),"")) | I10: =IF(I$4>Settings!$B$6,"",IFERROR(COUNTIFS(Risk_Log!$M$5:$M$504,">="&Settings!$B$5,Risk_Log!$M$5:$M$504,"<="&EOMONTH(I$4,0),Risk_Log!$N$5:$N$504,"No")/COUNTIFS(Risk_Log!$M$5:$M$504,">="&Settings!$B$5,Risk_Log!$M$5:$M$504,"<="&EOMONTH(I$4,0)),"")) -> 1 | J10: =IF(J$4>Settings!$B$6,"",IFERROR(COUNTIFS(Risk_Log!$M$5:$M$504,">="&Settings!$B$5,Risk_Log!$M$5:$M$504,"<="&EOMONTH(J$4,0),Risk_Log!$N$5:$N$504,"No")/COUNTIFS(Risk_Log!$M$5:$M$504,">="&Settings!$B$5,Risk_Log!$M$5:$M$504,"<="&EOMONTH(J$4,0)),"")) -> 1 | K10: =IF(K$4>Settings!$B$6,"",IFERROR(COUNTIFS(Risk_Log!$M$5:$M$504,">="&Settings!$B$5,Risk_Log!$M$5:$M$504,"<="&EOMONTH(K$4,0),Risk_Log!$N$5:$N$504,"No")/COUNTIFS(Risk_Log!$M$5:$M$504,">="&Settings!$B$5,Risk_Log!$M$5:$M$504,"<="&EOMONTH(K$4,0)),"")) -> 1 | L10: =IF(L$4>Settings!$B$6,"",IFERROR(COUNTIFS(Risk_Log!$M$5:$M$504,">="&Settings!$B$5,Risk_Log!$M$5:$M$504,"<="&EOMONTH(L$4,0),Risk_Log!$N$5:$N$504,"No")/COUNTIFS(Risk_Log!$M$5:$M$504,">="&Settings!$B$5,Risk_Log!$M$5:$M$504,"<="&EOMONTH(L$4,0)),"")) -> 0.77777778 | M10: =IF(M$4>Settings!$B$6,"",IFERROR(COUNTIFS(Risk_Log!$M$5:$M$504,">="&Settings!$B$5,Risk_Log!$M$5:$M$504,"<="&EOMONTH(M$4,0),Risk_Log!$N$5:$N$504,"No")/COUNTIFS(Risk_Log!$M$5:$M$504,">="&Settings!$B$5,Risk_Log!$M$5:$M$504,"<="&EOMONTH(M$4,0)),"")) -> 0.8 | N10: =IF(N$4>Settings!$B$6,"",IFERROR(COUNTIFS(Risk_Log!$M$5:$M$504,">="&Settings!$B$5,Risk_Log!$M$5:$M$504,"<="&EOMONTH(N$4,0),Risk_Log!$N$5:$N$504,"No")/COUNTIFS(Risk_Log!$M$5:$M$504,">="&Settings!$B$5,Risk_Log!$M$5:$M$504,"<="&EOMONTH(N$4,0)),"")) -> 0.8 | ... R10: =IF(R$4>Settings!$B$6,"",IFERROR(COUNTIFS(Risk_Log!$M$5:$M$504,">="&Settings!$B$5,Risk_Log!$M$5:$M$504,"<="&EOMONTH(R$4,0),Risk_Log!$N$5:$N$504,"No")/COUNTIFS(Risk_Log!$M$5:$M$504,">="&Settings!$B$5,Risk_Log!$M$5:$M$504,"<="&EOMONTH(R$4,0)),"")) | S10: =IFERROR(LOOKUP(2,1/(G10:R10<>""),G10:R10),"") -> 0.8125 | T10: =IF(S10="","",IF($D10="Higher",IF(S10>=$E10,"GREEN",IF(S10>=$F10,"AMBER","RED")),IF(S10<=$E10,"GREEN",IF(S10<=$F10,"AMBER","RED")))) -> AMBER | U10: =COUNTIF(G29:R29,"GREEN") -> 3 | V10: =COUNTIF(G29:R29,"RED") -> 0
A11: 7 | B11: =KPI_Targets!B11 -> Issue Resolution Time | C11: =KPI_Targets!E11 -> days | D11: =KPI_Targets!F11 -> Lower | E11: =KPI_Targets!G11 -> 7 | F11: =KPI_Targets!H11 -> 14 | G11: =IF(G$4>Settings!$B$6,"",IFERROR(AVERAGEIFS(Issue_Log!$I$5:$I$504,Issue_Log!$H$5:$H$504,">="&G$4,Issue_Log!$H$5:$H$504,"<="&EOMONTH(G$4,0)),"")) -> 9.25 | H11: =IF(H$4>Settings!$B$6,"",IFERROR(AVERAGEIFS(Issue_Log!$I$5:$I$504,Issue_Log!$H$5:$H$504,">="&H$4,Issue_Log!$H$5:$H$504,"<="&EOMONTH(H$4,0)),"")) -> 15 | I11: =IF(I$4>Settings!$B$6,"",IFERROR(AVERAGEIFS(Issue_Log!$I$5:$I$504,Issue_Log!$H$5:$H$504,">="&I$4,Issue_Log!$H$5:$H$504,"<="&EOMONTH(I$4,0)),"")) -> 9.5714286 | J11: =IF(J$4>Settings!$B$6,"",IFERROR(AVERAGEIFS(Issue_Log!$I$5:$I$504,Issue_Log!$H$5:$H$504,">="&J$4,Issue_Log!$H$5:$H$504,"<="&EOMONTH(J$4,0)),"")) -> 4.3333333 | K11: =IF(K$4>Settings!$B$6,"",IFERROR(AVERAGEIFS(Issue_Log!$I$5:$I$504,Issue_Log!$H$5:$H$504,">="&K$4,Issue_Log!$H$5:$H$504,"<="&EOMONTH(K$4,0)),"")) -> 8 | L11: =IF(L$4>Settings!$B$6,"",IFERROR(AVERAGEIFS(Issue_Log!$I$5:$I$504,Issue_Log!$H$5:$H$504,">="&L$4,Issue_Log!$H$5:$H$504,"<="&EOMONTH(L$4,0)),"")) -> 4.4285714 | M11: =IF(M$4>Settings!$B$6,"",IFERROR(AVERAGEIFS(Issue_Log!$I$5:$I$504,Issue_Log!$H$5:$H$504,">="&M$4,Issue_Log!$H$5:$H$504,"<="&EOMONTH(M$4,0)),"")) -> 10.428571 | N11: =IF(N$4>Settings!$B$6,"",IFERROR(AVERAGEIFS(Issue_Log!$I$5:$I$504,Issue_Log!$H$5:$H$504,">="&N$4,Issue_Log!$H$5:$H$504,"<="&EOMONTH(N$4,0)),"")) -> 7.4 | ... R11: =IF(R$4>Settings!$B$6,"",IFERROR(AVERAGEIFS(Issue_Log!$I$5:$I$504,Issue_Log!$H$5:$H$504,">="&R$4,Issue_Log!$H$5:$H$504,"<="&EOMONTH(R$4,0)),"")) | S11: =IFERROR(LOOKUP(2,1/(G11:R11<>""),G11:R11),"") -> 5 | T11: =IF(S11="","",IF($D11="Higher",IF(S11>=$E11,"GREEN",IF(S11>=$F11,"AMBER","RED")),IF(S11<=$E11,"GREEN",IF(S11<=$F11,"AMBER","RED")))) -> GREEN | U11: =COUNTIF(G30:R30,"GREEN") -> 3 | V11: =COUNTIF(G30:R30,"RED") -> 1
A12: 8 | B12: =KPI_Targets!B12 -> Stakeholder Satisfaction | C12: =KPI_Targets!E12 -> score /5 | D12: =KPI_Targets!F12 -> Higher | E12: =KPI_Targets!G12 -> 4 | F12: =KPI_Targets!H12 -> 3.5 | G12: =IF(G$4>Settings!$B$6,"",IFERROR(AVERAGEIFS(Stakeholder_Survey!$I$5:$I$504,Stakeholder_Survey!$A$5:$A$504,">="&G$4,Stakeholder_Survey!$A$5:$A$504,"<="&EOMONTH(G$4,0)),"")) -> 3.3125 | H12: =IF(H$4>Settings!$B$6,"",IFERROR(AVERAGEIFS(Stakeholder_Survey!$I$5:$I$504,Stakeholder_Survey!$A$5:$A$504,">="&H$4,Stakeholder_Survey!$A$5:$A$504,"<="&EOMONTH(H$4,0)),"")) -> 3.3125 | I12: =IF(I$4>Settings!$B$6,"",IFERROR(AVERAGEIFS(Stakeholder_Survey!$I$5:$I$504,Stakeholder_Survey!$A$5:$A$504,">="&I$4,Stakeholder_Survey!$A$5:$A$504,"<="&EOMONTH(I$4,0)),"")) -> 3.625 | J12: =IF(J$4>Settings!$B$6,"",IFERROR(AVERAGEIFS(Stakeholder_Survey!$I$5:$I$504,Stakeholder_Survey!$A$5:$A$504,">="&J$4,Stakeholder_Survey!$A$5:$A$504,"<="&EOMONTH(J$4,0)),"")) -> 3.5 | K12: =IF(K$4>Settings!$B$6,"",IFERROR(AVERAGEIFS(Stakeholder_Survey!$I$5:$I$504,Stakeholder_Survey!$A$5:$A$504,">="&K$4,Stakeholder_Survey!$A$5:$A$504,"<="&EOMONTH(K$4,0)),"")) -> 3.875 | L12: =IF(L$4>Settings!$B$6,"",IFERROR(AVERAGEIFS(Stakeholder_Survey!$I$5:$I$504,Stakeholder_Survey!$A$5:$A$504,">="&L$4,Stakeholder_Survey!$A$5:$A$504,"<="&EOMONTH(L$4,0)),"")) -> 3.6875 | M12: =IF(M$4>Settings!$B$6,"",IFERROR(AVERAGEIFS(Stakeholder_Survey!$I$5:$I$504,Stakeholder_Survey!$A$5:$A$504,">="&M$4,Stakeholder_Survey!$A$5:$A$504,"<="&EOMONTH(M$4,0)),"")) -> 3.9166667 | N12: =IF(N$4>Settings!$B$6,"",IFERROR(AVERAGEIFS(Stakeholder_Survey!$I$5:$I$504,Stakeholder_Survey!$A$5:$A$504,">="&N$4,Stakeholder_Survey!$A$5:$A$504,"<="&EOMONTH(N$4,0)),"")) -> 4.1666667 | ... R12: =IF(R$4>Settings!$B$6,"",IFERROR(AVERAGEIFS(Stakeholder_Survey!$I$5:$I$504,Stakeholder_Survey!$A$5:$A$504,">="&R$4,Stakeholder_Survey!$A$5:$A$504,"<="&EOMONTH(R$4,0)),"")) | S12: =IFERROR(LOOKUP(2,1/(G12:R12<>""),G12:R12),"") -> 3.9166667 | T12: =IF(S12="","",IF($D12="Higher",IF(S12>=$E12,"GREEN",IF(S12>=$F12,"AMBER","RED")),IF(S12<=$E12,"GREEN",IF(S12<=$F12,"AMBER","RED")))) -> AMBER | U12: =COUNTIF(G31:R31,"GREEN") -> 2 | V12: =COUNTIF(G31:R31,"RED") -> 2
A13: 9 | B13: =KPI_Targets!B13 -> Resource Utilization Rate | C13: =KPI_Targets!E13 -> % | D13: =KPI_Targets!F13 -> Higher | E13: =KPI_Targets!G13 -> 0.85 | F13: =KPI_Targets!H13 -> 0.75 | G13: =IF(G$4>Settings!$B$6,"",IFERROR(SUMIFS(Resources!$E$5:$E$504,Resources!$A$5:$A$504,">="&G$4,Resources!$A$5:$A$504,"<="&EOMONTH(G$4,0))/SUMIFS(Resources!$D$5:$D$504,Resources!$A$5:$A$504,">="&G$4,Resources!$A$5:$A$504,"<="&EOMONTH(G$4,0)),"")) -> 0.84760638 | H13: =IF(H$4>Settings!$B$6,"",IFERROR(SUMIFS(Resources!$E$5:$E$504,Resources!$A$5:$A$504,">="&H$4,Resources!$A$5:$A$504,"<="&EOMONTH(H$4,0))/SUMIFS(Resources!$D$5:$D$504,Resources!$A$5:$A$504,">="&H$4,Resources!$A$5:$A$504,"<="&EOMONTH(H$4,0)),"")) -> 0.84244505 | I13: =IF(I$4>Settings!$B$6,"",IFERROR(SUMIFS(Resources!$E$5:$E$504,Resources!$A$5:$A$504,">="&I$4,Resources!$A$5:$A$504,"<="&EOMONTH(I$4,0))/SUMIFS(Resources!$D$5:$D$504,Resources!$A$5:$A$504,">="&I$4,Resources!$A$5:$A$504,"<="&EOMONTH(I$4,0)),"")) -> 0.82739362 | J13: =IF(J$4>Settings!$B$6,"",IFERROR(SUMIFS(Resources!$E$5:$E$504,Resources!$A$5:$A$504,">="&J$4,Resources!$A$5:$A$504,"<="&EOMONTH(J$4,0))/SUMIFS(Resources!$D$5:$D$504,Resources!$A$5:$A$504,">="&J$4,Resources!$A$5:$A$504,"<="&EOMONTH(J$4,0)),"")) -> 0.81758242 | K13: =IF(K$4>Settings!$B$6,"",IFERROR(SUMIFS(Resources!$E$5:$E$504,Resources!$A$5:$A$504,">="&K$4,Resources!$A$5:$A$504,"<="&EOMONTH(K$4,0))/SUMIFS(Resources!$D$5:$D$504,Resources!$A$5:$A$504,">="&K$4,Resources!$A$5:$A$504,"<="&EOMONTH(K$4,0)),"")) -> 0.82181122 | L13: =IF(L$4>Settings!$B$6,"",IFERROR(SUMIFS(Resources!$E$5:$E$504,Resources!$A$5:$A$504,">="&L$4,Resources!$A$5:$A$504,"<="&EOMONTH(L$4,0))/SUMIFS(Resources!$D$5:$D$504,Resources!$A$5:$A$504,">="&L$4,Resources!$A$5:$A$504,"<="&EOMONTH(L$4,0)),"")) -> 0.83489011 | M13: =IF(M$4>Settings!$B$6,"",IFERROR(SUMIFS(Resources!$E$5:$E$504,Resources!$A$5:$A$504,">="&M$4,Resources!$A$5:$A$504,"<="&EOMONTH(M$4,0))/SUMIFS(Resources!$D$5:$D$504,Resources!$A$5:$A$504,">="&M$4,Resources!$A$5:$A$504,"<="&EOMONTH(M$4,0)),"")) -> 0.81868557 | N13: =IF(N$4>Settings!$B$6,"",IFERROR(SUMIFS(Resources!$E$5:$E$504,Resources!$A$5:$A$504,">="&N$4,Resources!$A$5:$A$504,"<="&EOMONTH(N$4,0))/SUMIFS(Resources!$D$5:$D$504,Resources!$A$5:$A$504,">="&N$4,Resources!$A$5:$A$504,"<="&EOMONTH(N$4,0)),"")) -> 0.84076087 | ... R13: =IF(R$4>Settings!$B$6,"",IFERROR(SUMIFS(Resources!$E$5:$E$504,Resources!$A$5:$A$504,">="&R$4,Resources!$A$5:$A$504,"<="&EOMONTH(R$4,0))/SUMIFS(Resources!$D$5:$D$504,Resources!$A$5:$A$504,">="&R$4,Resources!$A$5:$A$504,"<="&EOMONTH(R$4,0)),"")) | S13: =IFERROR(LOOKUP(2,1/(G13:R13<>""),G13:R13),"") -> 0.86126374 | T13: =IF(S13="","",IF($D13="Higher",IF(S13>=$E13,"GREEN",IF(S13>=$F13,"AMBER","RED")),IF(S13<=$E13,"GREEN",IF(S13<=$F13,"AMBER","RED")))) -> GREEN | U13: =COUNTIF(G32:R32,"GREEN") -> 1 | V13: =COUNTIF(G32:R32,"RED") -> 0
A14: 10 | B14: =KPI_Targets!B14 -> Project Success Rate | C14: =KPI_Targets!E14 -> % | D14: =KPI_Targets!F14 -> Higher | E14: =KPI_Targets!G14 -> 0.8 | F14: =KPI_Targets!H14 -> 0.65 | G14: =IF(G$4>Settings!$B$6,"",IFERROR(COUNTIFS(Projects!$I$5:$I$104,"Completed",Projects!$H$5:$H$104,">="&Settings!$B$5,Projects!$H$5:$H$104,"<="&EOMONTH(G$4,0),Projects!$P$5:$P$104,"Yes")/COUNTIFS(Projects!$I$5:$I$104,"Completed",Projects!$H$5:$H$104,">="&Settings!$B$5,Projects!$H$5:$H$104,"<="&EOMONTH(G$4,0)),"")) | H14: =IF(H$4>Settings!$B$6,"",IFERROR(COUNTIFS(Projects!$I$5:$I$104,"Completed",Projects!$H$5:$H$104,">="&Settings!$B$5,Projects!$H$5:$H$104,"<="&EOMONTH(H$4,0),Projects!$P$5:$P$104,"Yes")/COUNTIFS(Projects!$I$5:$I$104,"Completed",Projects!$H$5:$H$104,">="&Settings!$B$5,Projects!$H$5:$H$104,"<="&EOMONTH(H$4,0)),"")) | I14: =IF(I$4>Settings!$B$6,"",IFERROR(COUNTIFS(Projects!$I$5:$I$104,"Completed",Projects!$H$5:$H$104,">="&Settings!$B$5,Projects!$H$5:$H$104,"<="&EOMONTH(I$4,0),Projects!$P$5:$P$104,"Yes")/COUNTIFS(Projects!$I$5:$I$104,"Completed",Projects!$H$5:$H$104,">="&Settings!$B$5,Projects!$H$5:$H$104,"<="&EOMONTH(I$4,0)),"")) | J14: =IF(J$4>Settings!$B$6,"",IFERROR(COUNTIFS(Projects!$I$5:$I$104,"Completed",Projects!$H$5:$H$104,">="&Settings!$B$5,Projects!$H$5:$H$104,"<="&EOMONTH(J$4,0),Projects!$P$5:$P$104,"Yes")/COUNTIFS(Projects!$I$5:$I$104,"Completed",Projects!$H$5:$H$104,">="&Settings!$B$5,Projects!$H$5:$H$104,"<="&EOMONTH(J$4,0)),"")) -> 1 | K14: =IF(K$4>Settings!$B$6,"",IFERROR(COUNTIFS(Projects!$I$5:$I$104,"Completed",Projects!$H$5:$H$104,">="&Settings!$B$5,Projects!$H$5:$H$104,"<="&EOMONTH(K$4,0),Projects!$P$5:$P$104,"Yes")/COUNTIFS(Projects!$I$5:$I$104,"Completed",Projects!$H$5:$H$104,">="&Settings!$B$5,Projects!$H$5:$H$104,"<="&EOMONTH(K$4,0)),"")) -> 1 | L14: =IF(L$4>Settings!$B$6,"",IFERROR(COUNTIFS(Projects!$I$5:$I$104,"Completed",Projects!$H$5:$H$104,">="&Settings!$B$5,Projects!$H$5:$H$104,"<="&EOMONTH(L$4,0),Projects!$P$5:$P$104,"Yes")/COUNTIFS(Projects!$I$5:$I$104,"Completed",Projects!$H$5:$H$104,">="&Settings!$B$5,Projects!$H$5:$H$104,"<="&EOMONTH(L$4,0)),"")) -> 0.5 | M14: =IF(M$4>Settings!$B$6,"",IFERROR(COUNTIFS(Projects!$I$5:$I$104,"Completed",Projects!$H$5:$H$104,">="&Settings!$B$5,Projects!$H$5:$H$104,"<="&EOMONTH(M$4,0),Projects!$P$5:$P$104,"Yes")/COUNTIFS(Projects!$I$5:$I$104,"Completed",Projects!$H$5:$H$104,">="&Settings!$B$5,Projects!$H$5:$H$104,"<="&EOMONTH(M$4,0)),"")) -> 0.33333333 | N14: =IF(N$4>Settings!$B$6,"",IFERROR(COUNTIFS(Projects!$I$5:$I$104,"Completed",Projects!$H$5:$H$104,">="&Settings!$B$5,Projects!$H$5:$H$104,"<="&EOMONTH(N$4,0),Projects!$P$5:$P$104,"Yes")/COUNTIFS(Projects!$I$5:$I$104,"Completed",Projects!$H$5:$H$104,">="&Settings!$B$5,Projects!$H$5:$H$104,"<="&EOMONTH(N$4,0)),"")) -> 0.5 | ... R14: =IF(R$4>Settings!$B$6,"",IFERROR(COUNTIFS(Projects!$I$5:$I$104,"Completed",Projects!$H$5:$H$104,">="&Settings!$B$5,Projects!$H$5:$H$104,"<="&EOMONTH(R$4,0),Projects!$P$5:$P$104,"Yes")/COUNTIFS(Projects!$I$5:$I$104,"Completed",Projects!$H$5:$H$104,">="&Settings!$B$5,Projects!$H$5:$H$104,"<="&EOMONTH(R$4,0)),"")) | S14: =IFERROR(LOOKUP(2,1/(G14:R14<>""),G14:R14),"") -> 0.6 | T14: =IF(S14="","",IF($D14="Higher",IF(S14>=$E14,"GREEN",IF(S14>=$F14,"AMBER","RED")),IF(S14<=$E14,"GREEN",IF(S14<=$F14,"AMBER","RED")))) -> RED | U14: =COUNTIF(G33:R33,"GREEN") -> 2 | V14: =COUNTIF(G33:R33,"RED") -> 5
A15: 11 | B15: =KPI_Targets!B15 -> Milestone Completion Rate | C15: =KPI_Targets!E15 -> % | D15: =KPI_Targets!F15 -> Higher | E15: =KPI_Targets!G15 -> 0.9 | F15: =KPI_Targets!H15 -> 0.8 | G15: =IF(G$4>Settings!$B$6,"",IFERROR(COUNTIFS(Milestones!$E$5:$E$504,">="&G$4,Milestones!$E$5:$E$504,"<="&EOMONTH(G$4,0),Milestones!$H$5:$H$504,"Yes")/COUNTIFS(Milestones!$E$5:$E$504,">="&G$4,Milestones!$E$5:$E$504,"<="&EOMONTH(G$4,0)),"")) -> 0.4 | H15: =IF(H$4>Settings!$B$6,"",IFERROR(COUNTIFS(Milestones!$E$5:$E$504,">="&H$4,Milestones!$E$5:$E$504,"<="&EOMONTH(H$4,0),Milestones!$H$5:$H$504,"Yes")/COUNTIFS(Milestones!$E$5:$E$504,">="&H$4,Milestones!$E$5:$E$504,"<="&EOMONTH(H$4,0)),"")) -> 0.6 | I15: =IF(I$4>Settings!$B$6,"",IFERROR(COUNTIFS(Milestones!$E$5:$E$504,">="&I$4,Milestones!$E$5:$E$504,"<="&EOMONTH(I$4,0),Milestones!$H$5:$H$504,"Yes")/COUNTIFS(Milestones!$E$5:$E$504,">="&I$4,Milestones!$E$5:$E$504,"<="&EOMONTH(I$4,0)),"")) -> 1 | J15: =IF(J$4>Settings!$B$6,"",IFERROR(COUNTIFS(Milestones!$E$5:$E$504,">="&J$4,Milestones!$E$5:$E$504,"<="&EOMONTH(J$4,0),Milestones!$H$5:$H$504,"Yes")/COUNTIFS(Milestones!$E$5:$E$504,">="&J$4,Milestones!$E$5:$E$504,"<="&EOMONTH(J$4,0)),"")) -> 0.8 | K15: =IF(K$4>Settings!$B$6,"",IFERROR(COUNTIFS(Milestones!$E$5:$E$504,">="&K$4,Milestones!$E$5:$E$504,"<="&EOMONTH(K$4,0),Milestones!$H$5:$H$504,"Yes")/COUNTIFS(Milestones!$E$5:$E$504,">="&K$4,Milestones!$E$5:$E$504,"<="&EOMONTH(K$4,0)),"")) -> 0.4 | L15: =IF(L$4>Settings!$B$6,"",IFERROR(COUNTIFS(Milestones!$E$5:$E$504,">="&L$4,Milestones!$E$5:$E$504,"<="&EOMONTH(L$4,0),Milestones!$H$5:$H$504,"Yes")/COUNTIFS(Milestones!$E$5:$E$504,">="&L$4,Milestones!$E$5:$E$504,"<="&EOMONTH(L$4,0)),"")) -> 0.4 | M15: =IF(M$4>Settings!$B$6,"",IFERROR(COUNTIFS(Milestones!$E$5:$E$504,">="&M$4,Milestones!$E$5:$E$504,"<="&EOMONTH(M$4,0),Milestones!$H$5:$H$504,"Yes")/COUNTIFS(Milestones!$E$5:$E$504,">="&M$4,Milestones!$E$5:$E$504,"<="&EOMONTH(M$4,0)),"")) -> 0.5 | N15: =IF(N$4>Settings!$B$6,"",IFERROR(COUNTIFS(Milestones!$E$5:$E$504,">="&N$4,Milestones!$E$5:$E$504,"<="&EOMONTH(N$4,0),Milestones!$H$5:$H$504,"Yes")/COUNTIFS(Milestones!$E$5:$E$504,">="&N$4,Milestones!$E$5:$E$504,"<="&EOMONTH(N$4,0)),"")) -> 0.5 | ... R15: =IF(R$4>Settings!$B$6,"",IFERROR(COUNTIFS(Milestones!$E$5:$E$504,">="&R$4,Milestones!$E$5:$E$504,"<="&EOMONTH(R$4,0),Milestones!$H$5:$H$504,"Yes")/COUNTIFS(Milestones!$E$5:$E$504,">="&R$4,Milestones!$E$5:$E$504,"<="&EOMONTH(R$4,0)),"")) | S15: =IFERROR(LOOKUP(2,1/(G15:R15<>""),G15:R15),"") -> 0.25 | T15: =IF(S15="","",IF($D15="Higher",IF(S15>=$E15,"GREEN",IF(S15>=$F15,"AMBER","RED")),IF(S15<=$E15,"GREEN",IF(S15<=$F15,"AMBER","RED")))) -> RED | U15: =COUNTIF(G34:R34,"GREEN") -> 2 | V15: =COUNTIF(G34:R34,"RED") -> 7
A16: 12 | B16: =KPI_Targets!B16 -> Project Quality Index | C16: =KPI_Targets!E16 -> % | D16: =KPI_Targets!F16 -> Higher | E16: =KPI_Targets!G16 -> 0.95 | F16: =KPI_Targets!H16 -> 0.85 | G16: =IF(G$4>Settings!$B$6,"",IFERROR(COUNTIFS(Quality_Log!$D$5:$D$504,">="&G$4,Quality_Log!$D$5:$D$504,"<="&EOMONTH(G$4,0),Quality_Log!$G$5:$G$504,"Yes")/COUNTIFS(Quality_Log!$D$5:$D$504,">="&G$4,Quality_Log!$D$5:$D$504,"<="&EOMONTH(G$4,0)),"")) -> 1 | H16: =IF(H$4>Settings!$B$6,"",IFERROR(COUNTIFS(Quality_Log!$D$5:$D$504,">="&H$4,Quality_Log!$D$5:$D$504,"<="&EOMONTH(H$4,0),Quality_Log!$G$5:$G$504,"Yes")/COUNTIFS(Quality_Log!$D$5:$D$504,">="&H$4,Quality_Log!$D$5:$D$504,"<="&EOMONTH(H$4,0)),"")) -> 0.8 | I16: =IF(I$4>Settings!$B$6,"",IFERROR(COUNTIFS(Quality_Log!$D$5:$D$504,">="&I$4,Quality_Log!$D$5:$D$504,"<="&EOMONTH(I$4,0),Quality_Log!$G$5:$G$504,"Yes")/COUNTIFS(Quality_Log!$D$5:$D$504,">="&I$4,Quality_Log!$D$5:$D$504,"<="&EOMONTH(I$4,0)),"")) -> 1 | J16: =IF(J$4>Settings!$B$6,"",IFERROR(COUNTIFS(Quality_Log!$D$5:$D$504,">="&J$4,Quality_Log!$D$5:$D$504,"<="&EOMONTH(J$4,0),Quality_Log!$G$5:$G$504,"Yes")/COUNTIFS(Quality_Log!$D$5:$D$504,">="&J$4,Quality_Log!$D$5:$D$504,"<="&EOMONTH(J$4,0)),"")) -> 0.6 | K16: =IF(K$4>Settings!$B$6,"",IFERROR(COUNTIFS(Quality_Log!$D$5:$D$504,">="&K$4,Quality_Log!$D$5:$D$504,"<="&EOMONTH(K$4,0),Quality_Log!$G$5:$G$504,"Yes")/COUNTIFS(Quality_Log!$D$5:$D$504,">="&K$4,Quality_Log!$D$5:$D$504,"<="&EOMONTH(K$4,0)),"")) -> 0.8 | L16: =IF(L$4>Settings!$B$6,"",IFERROR(COUNTIFS(Quality_Log!$D$5:$D$504,">="&L$4,Quality_Log!$D$5:$D$504,"<="&EOMONTH(L$4,0),Quality_Log!$G$5:$G$504,"Yes")/COUNTIFS(Quality_Log!$D$5:$D$504,">="&L$4,Quality_Log!$D$5:$D$504,"<="&EOMONTH(L$4,0)),"")) -> 1 | M16: =IF(M$4>Settings!$B$6,"",IFERROR(COUNTIFS(Quality_Log!$D$5:$D$504,">="&M$4,Quality_Log!$D$5:$D$504,"<="&EOMONTH(M$4,0),Quality_Log!$G$5:$G$504,"Yes")/COUNTIFS(Quality_Log!$D$5:$D$504,">="&M$4,Quality_Log!$D$5:$D$504,"<="&EOMONTH(M$4,0)),"")) -> 0.8 | N16: =IF(N$4>Settings!$B$6,"",IFERROR(COUNTIFS(Quality_Log!$D$5:$D$504,">="&N$4,Quality_Log!$D$5:$D$504,"<="&EOMONTH(N$4,0),Quality_Log!$G$5:$G$504,"Yes")/COUNTIFS(Quality_Log!$D$5:$D$504,">="&N$4,Quality_Log!$D$5:$D$504,"<="&EOMONTH(N$4,0)),"")) -> 1 | ... R16: =IF(R$4>Settings!$B$6,"",IFERROR(COUNTIFS(Quality_Log!$D$5:$D$504,">="&R$4,Quality_Log!$D$5:$D$504,"<="&EOMONTH(R$4,0),Quality_Log!$G$5:$G$504,"Yes")/COUNTIFS(Quality_Log!$D$5:$D$504,">="&R$4,Quality_Log!$D$5:$D$504,"<="&EOMONTH(R$4,0)),"")) | S16: =IFERROR(LOOKUP(2,1/(G16:R16<>""),G16:R16),"") -> 1 | T16: =IF(S16="","",IF($D16="Higher",IF(S16>=$E16,"GREEN",IF(S16>=$F16,"AMBER","RED")),IF(S16<=$E16,"GREEN",IF(S16<=$F16,"AMBER","RED")))) -> GREEN | U16: =COUNTIF(G35:R35,"GREEN") -> 6 | V16: =COUNTIF(G35:R35,"RED") -> 4
